Workbook

Sheet Petunjuk
B2: KASUMKM · BUKU KAS UMKM
B3: Cara Pakai File Ini
B4: Cukup 4 kolom setiap kali mencatat. Sisanya dihitung otomatis.
B6: UNTUK PEMILIK USAHA
B7: 1. | C7: Buka sheet TRANSAKSI (lihat tab di bawah).
B8: 2. | C8: Isi baris kosong paling bawah: Tanggal, Jenis (Masuk/Keluar), Nominal, Keterangan.
B9: 3. | C9: Kolom Kategori, Metode Bayar, dan Status BOLEH DIKOSONGKAN — nanti diisi admin.
B10: 4. | C10: Nominal ditulis angka saja, tanpa Rp dan tanpa titik. Contoh: 150000
B11: 5. | C11: Punya foto nota? Simpan di Google Drive, tempel tautannya di kolom Tautan Nota.
B12: 6. | C12: Catat setiap hari walau hanya satu transaksi. Tidak perlu rapi, yang penting tercatat.
B14: UNTUK ADMIN / PEMBUKU
B15: 1. | C15: Baris berwarna kuning = kategori belum diisi. Isi lewat dropdown di kolom Kategori.
B16: 2. | C16: Setelah benar, ubah Status menjadi 'Disetujui'. Kalau ragu pilih 'Perlu Perbaikan' dan tulis pertanyaan di kolom Catatan Admin.
B17: 3. | C17: Sheet CEK DATA menampilkan baris bermasalah (nominal kosong, tanggal aneh, duplikat).
B18: 4. | C18: Sheet DASHBOARD: ubah Bulan & Tahun — kartu, indikator, dan grafik ikut berubah.
B19: 5. | C19: Akhir bulan: cetak sheet LABA RUGI menjadi PDF dan kirim ke pemilik usaha.
B21: CARA BACA DASHBOARD
B22: 1. | C22: Empat kartu di atas = Uang Masuk, Uang Keluar, Laba/Rugi, Saldo Kas bulan terpilih.
B23: 2. | C23: ▲ hijau = membaik dibanding bulan lalu, ▼ merah = menurun. Untuk Uang Keluar warnanya dibalik (naik = merah).
B24: 3. | C24: Lampu status: hijau SEHAT (laba positif), kuning IMBANG, merah WASPADA (boros).
B25: 4. | C25: Balok █ pada 'Uang Paling Banyak Keluar' menunjukkan besar pengeluaran per kategori.
B26: 5. | C26: Grafik di sebelah kanan: 12 bulan, tren harian, dan komposisi pengeluaran.
B28: PENTING
B29: 1. | C29: Jangan menghapus atau memindahkan kolom, karena rumus mengacu ke posisi kolom.
B30: 2. | C30: Kolom J (Bulan) di sheet Transaksi dan sheet DATA GRAFIK adalah pembantu rumus — biarkan saja.
B31: 3. | C31: Kapasitas 500 baris transaksi. Kalau penuh, buat file baru untuk tahun berikutnya.
B32: 4. | C32: Sel rumus dikunci agar tidak tertimpa. Buka lewat Review → Unprotect Sheet (tanpa password).
B33: 5. | C33: Ingin diisi dari HP? Unggah ke Google Drive, buka dengan Google Spreadsheet.

Sheet Profil Usaha
B2: KASUMKM · IDENTITAS
B3: Profil Usaha
B4: Diisi satu kali oleh admin saat file dibuat.
B6: DATA USAHA
B7: Nama Usaha | C7: Toko Maju
B8: Nama Pemilik | C8: Bu Siti
B9: Jenis Usaha | C9: Warung / Toko Kelontong
B10: No. HP / WhatsApp | C10: 0812-3456-7890
B11: Alamat | C11: Jl. Merdeka No. 12
B13: PEMBUKUAN
B14: Modal Awal / Saldo Kas Awal (Rp) | C14: 5000000
B15: Bulan Mulai Pembukuan | C15: Mei 2026
B16: Nama Admin / Pembuku | C16: Admin KasUMKM
B18: Saldo Kas di Dashboard = Modal Awal di atas + seluruh transaksi yang tercatat.

Sheet Transaksi
A1: Tanggal | B1: Jenis | C1: Nominal (Rp) | D1: Keterangan | E1: Kategori | F1: Metode Bayar | G1: Status | H1: Catatan Admin | I1: Tautan Nota | J1: Bulan (bantu)
A2: 46143 | B2: Masuk | C2: 304000 | D2: penjualan harian | E2: Penjualan Tunai | F2: Tunai | G2: Disetujui | J2: =IF($A2="","",TEXT($A2,"yyyy-mm"))
A3: 46143 | B3: Keluar | C3: 68000 | D3: pulsa internet | E3: Pulsa & Internet | F3: Tunai | G3: Disetujui | J3: =IF($A3="","",TEXT($A3,"yyyy-mm"))
A4: 46144 | B4: Masuk | C4: 746000 | D4: penjualan tunai kasir | E4: Penjualan Tunai | F4: Tunai | G4: Disetujui | J4: =IF($A4="","",TEXT($A4,"yyyy-mm"))
A5: 46144 | B5: Keluar | C5: 242000 | D5: beli bahan baku | E5: Bahan Baku | F5: Tunai | G5: Disetujui | J5: =IF($A5="","",TEXT($A5,"yyyy-mm"))
A6: 46145 | B6: Masuk | C6: 221000 | D6: penjualan harian | E6: Penjualan Tunai | F6: Tunai | G6: Disetujui | J6: =IF($A6="","",TEXT($A6,"yyyy-mm"))
A7: 46145 | B7: Keluar | C7: 309000 | D7: beli bahan baku | E7: Bahan Baku | F7: Tunai | G7: Disetujui | J7: =IF($A7="","",TEXT($A7,"yyyy-mm"))
A8: 46146 | B8: Masuk | C8: 378000 | D8: penjualan tunai kasir | E8: Penjualan Online | F8: Tunai | G8: Disetujui | J8: =IF($A8="","",TEXT($A8,"yyyy-mm"))
A9: 46147 | B9: Masuk | C9: 749000 | D9: penjualan harian | E9: Penjualan Tunai | F9: Tunai | G9: Disetujui | J9: =IF($A9="","",TEXT($A9,"yyyy-mm"))
A10: 46147 | B10: Masuk | C10: 376000 | D10: penjualan tunai kasir | E10: Penjualan Tunai | F10: Tunai | G10: Disetujui | J10: =IF($A10="","",TEXT($A10,"yyyy-mm"))
A11: 46147 | B11: Keluar | C11: 1500000 | D11: gaji karyawan | E11: Gaji & Upah | F11: Transfer Bank | G11: Disetujui | J11: =IF($A11="","",TEXT($A11,"yyyy-mm"))
A12: 46147 | B12: Keluar | C12: 1000000 | D12: sewa kios | E12: Sewa Tempat | F12: Transfer Bank | G12: Disetujui | J12: =IF($A12="","",TEXT($A12,"yyyy-mm"))
A13: 46148 | B13: Masuk | C13: 579000 | D13: penjualan tunai kasir | E13: Penjualan Tunai | F13: Tunai | G13: Disetujui | J13: =IF($A13="","",TEXT($A13,"yyyy-mm"))
... A119: 46192 | B119: Masuk | C119: 415000 | D119: jualan warung | E119: Penjualan Online | F119: Tunai | G119: Disetujui | J119: =IF($A119="","",TEXT($A119,"yyyy-mm"))
A120: 46193 | B120: Masuk | C120: 576000 | D120: jualan sore | J120: =IF($A120="","",TEXT($A120,"yyyy-mm"))
A121: 46193 | B121: Keluar | C121: 143000 | D121: beli bahan baku | J121: =IF($A121="","",TEXT($A121,"yyyy-mm"))
A122: 46194 | B122: Masuk | C122: 224000 | D122: pesanan online | J122: =IF($A122="","",TEXT($A122,"yyyy-mm"))
A123: 46194 | B123: Keluar | C123: 349000 | D123: belanja pasar | J123: =IF($A123="","",TEXT($A123,"yyyy-mm"))
A124: 46195 | B124: Masuk | C124: 524000 | D124: pesanan online | J124: =IF($A124="","",TEXT($A124,"yyyy-mm"))
A125: 46195 | B125: Masuk | C125: 290000 | D125: jualan warung | J125: =IF($A125="","",TEXT($A125,"yyyy-mm"))
A126: 46195 | B126: Keluar | C126: 223000 | D126: beli bahan baku | J126: =IF($A126="","",TEXT($A126,"yyyy-mm"))
A127: 46196 | B127: Masuk | C127: 316000 | D127: jualan warung | J127: =IF($A127="","",TEXT($A127,"yyyy-mm"))
A128: 46196 | B128: Keluar | C128: 283000 | D128: beli plastik kemasan | J128: =IF($A128="","",TEXT($A128,"yyyy-mm"))
A129: 46197 | B129: Masuk | C129: 497000 | D129: jualan warung | J129: =IF($A129="","",TEXT($A129,"yyyy-mm"))
A130: 46197 | B130: Keluar | C130: 207000 | D130: beli bahan baku | J130: =IF($A130="","",TEXT($A130,"yyyy-mm"))
A131: 46198 | B131: Masuk | C131: 496000 | D131: jualan sore | J131: =IF($A131="","",TEXT($A131,"yyyy-mm"))
... A142: 46203 | B142: Masuk | C142: 425000 | D142: penjualan harian | J142: =IF($A142="","",TEXT($A142,"yyyy-mm"))
J143: =IF($A143="","",TEXT($A143,"yyyy-mm"))
J144: =IF($A144="","",TEXT($A144,"yyyy-mm"))
J145: =IF($A145="","",TEXT($A145,"yyyy-mm"))
J146: =IF($A146="","",TEXT($A146,"yyyy-mm"))
J147: =IF($A147="","",TEXT($A147,"yyyy-mm"))
J148: =IF($A148="","",TEXT($A148,"yyyy-mm"))
J149: =IF($A149="","",TEXT($A149,"yyyy-mm"))
J150: =IF($A150="","",TEXT($A150,"yyyy-mm"))
J151: =IF($A151="","",TEXT($A151,"yyyy-mm"))
J152: =IF($A152="","",TEXT($A152,"yyyy-mm"))
J153: =IF($A153="","",TEXT($A153,"yyyy-mm"))
J154: =IF($A154="","",TEXT($A154,"yyyy-mm"))
... J501: =IF($A501="","",TEXT($A501,"yyyy-mm"))

Sheet Dashboard
B2: KASUMKM · DASHBOARD KEUANGAN
B3: =IF('Profil Usaha'!$C$7="","Dashboard Keuangan",'Profil Usaha'!$C$7)
B4: Ubah Bulan & Tahun — semua kartu, indikator, dan grafik ikut berubah.
B6: Bulan (1-12) | C6: 6 | E6: Tahun | F6: 2026
B7: =CHOOSE($C$6,"Januari","Februari","Maret","April","Mei","Juni","Juli","Agustus","September","Oktober","November","Desember")&" "&$F$6 | E7: =IF($L$8>0,"● SEHAT · laba bulan ini positif",IF($L$8=0,"● IMBANG · belum ada laba","● WASPADA · pengeluaran lebih besar"))
B8: kunci | C8: =TEXT(DATE($F$6,$C$6,1),"yyyy-mm") | E8: kunci bulan lalu | F8: =TEXT(DATE($F$6,$C$6-1,1),"yyyy-mm") | H8: ='Data Grafik'!$B$4 | I8: ='Data Grafik'!$C$4 | J8: ='Data Grafik'!$B$5 | K8: ='Data Grafik'!$C$5 | L8: ='Data Grafik'!$B$6 | M8: ='Data Grafik'!$C$6 | N8: ='Data Grafik'!$B$7 | O8: ='Data Grafik'!$C$7
B10: UANG MASUK BULAN INI | E10: UANG KELUAR BULAN INI
B11: =$H$8 | E11: =$J$8
B12: =IF($I$8=0,"belum ada pembanding bulan lalu",IF($H$8>=$I$8,"▲ ","▼ ")&TEXT(ABS($H$8-$I$8)/ABS($I$8),"0%")&" vs bulan lalu") | E12: =IF($K$8=0,"belum ada pembanding bulan lalu",IF($J$8>=$K$8,"▲ ","▼ ")&TEXT(ABS($J$8-$K$8)/ABS($K$8),"0%")&" vs bulan lalu")
B14: LABA / RUGI BULAN INI | E14: SALDO KAS SAMPAI AKHIR BULAN
B15: =$L$8 | E15: =$N$8
B16: =IF($M$8=0,"belum ada pembanding bulan lalu",IF($L$8>=$M$8,"▲ ","▼ ")&TEXT(ABS($L$8-$M$8)/ABS($M$8),"0%")&" vs bulan lalu") | E16: =IF($O$8=0,"belum ada pembanding bulan lalu",IF($N$8>=$O$8,"▲ ","▼ ")&TEXT(ABS($N$8-$O$8)/ABS($O$8),"0%")&" vs bulan lalu")
B18: RINGKASAN CEPAT
B19: Transaksi bulan ini | C19: ='Data Grafik'!$B$8 | E19: Belum dikategorikan | F19: ='Data Grafik'!$B$9
B20: Belum disetujui | C20: ='Data Grafik'!$B$10 | E20: Terakhir dicatat | F20: ='Data Grafik'!$B$11
B22: UANG PALING BANYAK KELUAR BULAN INI
B23: Kategori | C23: Jumlah | E23: Grafik
B24: =IF('Data Grafik'!$A$45="","—",'Data Grafik'!$A$45) | C24: =IF('Data Grafik'!$A$45="","",'Data Grafik'!$B$45) | E24: =IF(OR($C24="",$C24=0),"",REPT("█",MAX(1,ROUND(16*$C24/MAX($C$24:$C$29),0))))
B25: =IF('Data Grafik'!$A$46="","—",'Data Grafik'!$A$46) | C25: =IF('Data Grafik'!$A$46="","",'Data Grafik'!$B$46) | E25: =IF(OR($C25="",$C25=0),"",REPT("█",MAX(1,ROUND(16*$C25/MAX($C$24:$C$29),0))))
B26: =IF('Data Grafik'!$A$47="","—",'Data Grafik'!$A$47) | C26: =IF('Data Grafik'!$A$47="","",'Data Grafik'!$B$47) | E26: =IF(OR($C26="",$C26=0),"",REPT("█",MAX(1,ROUND(16*$C26/MAX($C$24:$C$29),0))))
B27: =IF('Data Grafik'!$A$48="","—",'Data Grafik'!$A$48) | C27: =IF('Data Grafik'!$A$48="","",'Data Grafik'!$B$48) | E27: =IF(OR($C27="",$C27=0),"",REPT("█",MAX(1,ROUND(16*$C27/MAX($C$24:$C$29),0))))
B28: =IF('Data Grafik'!$A$49="","—",'Data Grafik'!$A$49) | C28: =IF('Data Grafik'!$A$49="","",'Data Grafik'!$B$49) | E28: =IF(OR($C28="",$C28=0),"",REPT("█",MAX(1,ROUND(16*$C28/MAX($C$24:$C$29),0))))
B29: =IF('Data Grafik'!$A$50="","—",'Data Grafik'!$A$50) | C29: =IF('Data Grafik'!$A$50="","",'Data Grafik'!$B$50) | E29: =IF(OR($C29="",$C29=0),"",REPT("█",MAX(1,ROUND(16*$C29/MAX($C$24:$C$29),0))))
B31: Balok █ makin panjang = pengeluaran makin besar. Grafik lengkap ada di sebelah kanan →

Sheet Laba Rugi
B2: KASUMKM · LAPORAN BULANAN
B3: Laporan Laba Rugi
B4: Bulan mengikuti pilihan di sheet Dashboard. Siap dicetak / disimpan sebagai PDF.
B6: ="Periode: "&CHOOSE(Dashboard!$C$6,"Januari","Februari","Maret","April","Mei","Juni","Juli","Agustus","September","Oktober","November","Desember")&" "&Dashboard!$F$6&" · "&IF('Profil Usaha'!$C$7="","(Nama Usaha)",'Profil Usaha'!$C$7)
B8: PEMASUKAN | C8: Jumlah (Rp) | D8: % dari Pemasukan
B9: =Kategori!$B$7 | C9: =SUMIFS(Transaksi!$C:$C,Transaksi!$J:$J,Dashboard!$C$8,Transaksi!$B:$B,"Masuk",Transaksi!$E:$E,$B9) | D9: =IF($C$15=0,"",$C9/$C$15)
B10: =Kategori!$B$8 | C10: =SUMIFS(Transaksi!$C:$C,Transaksi!$J:$J,Dashboard!$C$8,Transaksi!$B:$B,"Masuk",Transaksi!$E:$E,$B10) | D10: =IF($C$15=0,"",$C10/$C$15)
B11: =Kategori!$B$9 | C11: =SUMIFS(Transaksi!$C:$C,Transaksi!$J:$J,Dashboard!$C$8,Transaksi!$B:$B,"Masuk",Transaksi!$E:$E,$B11) | D11: =IF($C$15=0,"",$C11/$C$15)
B12: =Kategori!$B$10 | C12: =SUMIFS(Transaksi!$C:$C,Transaksi!$J:$J,Dashboard!$C$8,Transaksi!$B:$B,"Masuk",Transaksi!$E:$E,$B12) | D12: =IF($C$15=0,"",$C12/$C$15)
B13: =Kategori!$B$11 | C13: =SUMIFS(Transaksi!$C:$C,Transaksi!$J:$J,Dashboard!$C$8,Transaksi!$B:$B,"Masuk",Transaksi!$E:$E,$B13) | D13: =IF($C$15=0,"",$C13/$C$15)
B14: Belum dikategorikan | C14: =SUMIFS(Transaksi!$C:$C,Transaksi!$J:$J,Dashboard!$C$8,Transaksi!$B:$B,"Masuk",Transaksi!$E:$E,"") | D14: =IF($C$15=0,"",$C14/$C$15)
B15: TOTAL PEMASUKAN | C15: =SUM(C9:C14) | D15: =IF($C$15=0,"",$C15/$C$15)
B17: PENGELUARAN | C17: Jumlah (Rp) | D17: % dari Pemasukan
B18: =Kategori!$C$7 | C18: =SUMIFS(Transaksi!$C:$C,Transaksi!$J:$J,Dashboard!$C$8,Transaksi!$B:$B,"Keluar",Transaksi!$E:$E,$B18) | D18: =IF($C$15=0,"",$C18/$C$15)
B19: =Kategori!$C$8 | C19: =SUMIFS(Transaksi!$C:$C,Transaksi!$J:$J,Dashboard!$C$8,Transaksi!$B:$B,"Keluar",Transaksi!$E:$E,$B19) | D19: =IF($C$15=0,"",$C19/$C$15)
B20: =Kategori!$C$9 | C20: =SUMIFS(Transaksi!$C:$C,Transaksi!$J:$J,Dashboard!$C$8,Transaksi!$B:$B,"Keluar",Transaksi!$E:$E,$B20) | D20: =IF($C$15=0,"",$C20/$C$15)
B21: =Kategori!$C$10 | C21: =SUMIFS(Transaksi!$C:$C,Transaksi!$J:$J,Dashboard!$C$8,Transaksi!$B:$B,"Keluar",Transaksi!$E:$E,$B21) | D21: =IF($C$15=0,"",$C21/$C$15)
B22: =Kategori!$C$11 | C22: =SUMIFS(Transaksi!$C:$C,Transaksi!$J:$J,Dashboard!$C$8,Transaksi!$B:$B,"Keluar",Transaksi!$E:$E,$B22) | D22: =IF($C$15=0,"",$C22/$C$15)
B23: =Kategori!$C$12 | C23: =SUMIFS(Transaksi!$C:$C,Transaksi!$J:$J,Dashboard!$C$8,Transaksi!$B:$B,"Keluar",Transaksi!$E:$E,$B23) | D23: =IF($C$15=0,"",$C23/$C$15)
B24: =Kategori!$C$13 | C24: =SUMIFS(Transaksi!$C:$C,Transaksi!$J:$J,Dashboard!$C$8,Transaksi!$B:$B,"Keluar",Transaksi!$E:$E,$B24) | D24: =IF($C$15=0,"",$C24/$C$15)
B25: =Kategori!$C$14 | C25: =SUMIFS(Transaksi!$C:$C,Transaksi!$J:$J,Dashboard!$C$8,Transaksi!$B:$B,"Keluar",Transaksi!$E:$E,$B25) | D25: =IF($C$15=0,"",$C25/$C$15)
B26: =Kategori!$C$15 | C26: =SUMIFS(Transaksi!$C:$C,Transaksi!$J:$J,Dashboard!$C$8,Transaksi!$B:$B,"Keluar",Transaksi!$E:$E,$B26) | D26: =IF($C$15=0,"",$C26/$C$15)
B27: =Kategori!$C$16 | C27: =SUMIFS(Transaksi!$C:$C,Transaksi!$J:$J,Dashboard!$C$8,Transaksi!$B:$B,"Keluar",Transaksi!$E:$E,$B27) | D27: =IF($C$15=0,"",$C27/$C$15)
B28: =Kategori!$C$17 | C28: =SUMIFS(Transaksi!$C:$C,Transaksi!$J:$J,Dashboard!$C$8,Transaksi!$B:$B,"Keluar",Transaksi!$E:$E,$B28) | D28: =IF($C$15=0,"",$C28/$C$15)
B29: =Kategori!$C$18 | C29: =SUMIFS(Transaksi!$C:$C,Transaksi!$J:$J,Dashboard!$C$8,Transaksi!$B:$B,"Keluar",Transaksi!$E:$E,$B29) | D29: =IF($C$15=0,"",$C29/$C$15)
B30: Belum dikategorikan | C30: =SUMIFS(Transaksi!$C:$C,Transaksi!$J:$J,Dashboard!$C$8,Transaksi!$B:$B,"Keluar",Transaksi!$E:$E,"") | D30: =IF($C$15=0,"",$C30/$C$15)
B31: TOTAL PENGELUARAN | C31: =SUM(C18:C30) | D31: =IF($C$15=0,"",$C31/$C$15)
B33: LABA / RUGI BERSIH | C33: =C15-C31 | D33: =IF($C$15=0,"",$C33/$C$15)
B35: Catatan Admin untuk Pemilik Usaha

Sheet Arus Kas Harian
A1: Arus Kas Harian
A2: ="Mengikuti Bulan & Tahun di sheet Dashboard · "&CHOOSE(Dashboard!$C$6,"Januari","Februari","Maret","April","Mei","Juni","Juli","Agustus","September","Oktober","November","Desember")&" "&Dashboard!$F$6
A4: Tanggal | B4: Uang Masuk | C4: Uang Keluar | D4: Selisih Hari Ini | E4: Saldo Berjalan | F4: Grafik Masuk | G4: Grafik Keluar | H4: Hari (bantu)
A5: =IF(1>DAY(EOMONTH(DATE(Dashboard!$F$6,Dashboard!$C$6,1),0)),"",DATE(Dashboard!$F$6,Dashboard!$C$6,1)) | B5: =IF($A5="","",SUMIFS(Transaksi!$C:$C,Transaksi!$A:$A,$A5,Transaksi!$B:$B,"Masuk")) | C5: =IF($A5="","",SUMIFS(Transaksi!$C:$C,Transaksi!$A:$A,$A5,Transaksi!$B:$B,"Keluar")) | D5: =IF($A5="","",$B5-$C5) | E5: =IF($A5="","",IF('Profil Usaha'!$C$14="",0,'Profil Usaha'!$C$14)+SUMIFS(Transaksi!$C:$C,Transaksi!$A:$A,"<"&$A5,Transaksi!$B:$B,"Masuk")-SUMIFS(Transaksi!$C:$C,Transaksi!$A:$A,"<"&$A5,Transaksi!$B:$B,"Keluar")+$D5) | F5: =IF(OR($A5="",$B5=0),"",REPT("█",MAX(1,ROUND(12*$B5/MAX($B$5:$B$35),0)))) | G5: =IF(OR($A5="",$C5=0),"",REPT("█",MAX(1,ROUND(12*$C5/MAX($C$5:$C$35),0)))) | H5: =IF($A5="","",DAY($A5))
A6: =IF(2>DAY(EOMONTH(DATE(Dashboard!$F$6,Dashboard!$C$6,1),0)),"",DATE(Dashboard!$F$6,Dashboard!$C$6,2)) | B6: =IF($A6="","",SUMIFS(Transaksi!$C:$C,Transaksi!$A:$A,$A6,Transaksi!$B:$B,"Masuk")) | C6: =IF($A6="","",SUMIFS(Transaksi!$C:$C,Transaksi!$A:$A,$A6,Transaksi!$B:$B,"Keluar")) | D6: =IF($A6="","",$B6-$C6) | E6: =IF($A6="","",$E5+$D6) | F6: =IF(OR($A6="",$B6=0),"",REPT("█",MAX(1,ROUND(12*$B6/MAX($B$5:$B$35),0)))) | G6: =IF(OR($A6="",$C6=0),"",REPT("█",MAX(1,ROUND(12*$C6/MAX($C$5:$C$35),0)))) | H6: =IF($A6="","",DAY($A6))
A7: =IF(3>DAY(EOMONTH(DATE(Dashboard!$F$6,Dashboard!$C$6,1),0)),"",DATE(Dashboard!$F$6,Dashboard!$C$6,3)) | B7: =IF($A7="","",SUMIFS(Transaksi!$C:$C,Transaksi!$A:$A,$A7,Transaksi!$B:$B,"Masuk")) | C7: =IF($A7="","",SUMIFS(Transaksi!$C:$C,Transaksi!$A:$A,$A7,Transaksi!$B:$B,"Keluar")) | D7: =IF($A7="","",$B7-$C7) | E7: =IF($A7="","",$E6+$D7) | F7: =IF(OR($A7="",$B7=0),"",REPT("█",MAX(1,ROUND(12*$B7/MAX($B$5:$B$35),0)))) | G7: =IF(OR($A7="",$C7=0),"",REPT("█",MAX(1,ROUND(12*$C7/MAX($C$5:$C$35),0)))) | H7: =IF($A7="","",DAY($A7))
A8: =IF(4>DAY(EOMONTH(DATE(Dashboard!$F$6,Dashboard!$C$6,1),0)),"",DATE(Dashboard!$F$6,Dashboard!$C$6,4)) | B8: =IF($A8="","",SUMIFS(Transaksi!$C:$C,Transaksi!$A:$A,$A8,Transaksi!$B:$B,"Masuk")) | C8: =IF($A8="","",SUMIFS(Transaksi!$C:$C,Transaksi!$A:$A,$A8,Transaksi!$B:$B,"Keluar")) | D8: =IF($A8="","",$B8-$C8) | E8: =IF($A8="","",$E7+$D8) | F8: =IF(OR($A8="",$B8=0),"",REPT("█",MAX(1,ROUND(12*$B8/MAX($B$5:$B$35),0)))) | G8: =IF(OR($A8="",$C8=0),"",REPT("█",MAX(1,ROUND(12*$C8/MAX($C$5:$C$35),0)))) | H8: =IF($A8="","",DAY($A8))
A9: =IF(5>DAY(EOMONTH(DATE(Dashboard!$F$6,Dashboard!$C$6,1),0)),"",DATE(Dashboard!$F$6,Dashboard!$C$6,5)) | B9: =IF($A9="","",SUMIFS(Transaksi!$C:$C,Transaksi!$A:$A,$A9,Transaksi!$B:$B,"Masuk")) | C9: =IF($A9="","",SUMIFS(Transaksi!$C:$C,Transaksi!$A:$A,$A9,Transaksi!$B:$B,"Keluar")) | D9: =IF($A9="","",$B9-$C9) | E9: =IF($A9="","",$E8+$D9) | F9: =IF(OR($A9="",$B9=0),"",REPT("█",MAX(1,ROUND(12*$B9/MAX($B$5:$B$35),0)))) | G9: =IF(OR($A9="",$C9=0),"",REPT("█",MAX(1,ROUND(12*$C9/MAX($C$5:$C$35),0)))) | H9: =IF($A9="","",DAY($A9))
A10: =IF(6>DAY(EOMONTH(DATE(Dashboard!$F$6,Dashboard!$C$6,1),0)),"",DATE(Dashboard!$F$6,Dashboard!$C$6,6)) | B10: =IF($A10="","",SUMIFS(Transaksi!$C:$C,Transaksi!$A:$A,$A10,Transaksi!$B:$B,"Masuk")) | C10: =IF($A10="","",SUMIFS(Transaksi!$C:$C,Transaksi!$A:$A,$A10,Transaksi!$B:$B,"Keluar")) | D10: =IF($A10="","",$B10-$C10) | E10: =IF($A10="","",$E9+$D10) | F10: =IF(OR($A10="",$B10=0),"",REPT("█",MAX(1,ROUND(12*$B10/MAX($B$5:$B$35),0)))) | G10: =IF(OR($A10="",$C10=0),"",REPT("█",MAX(1,ROUND(12*$C10/MAX($C$5:$C$35),0)))) | H10: =IF($A10="","",DAY($A10))
A11: =IF(7>DAY(EOMONTH(DATE(Dashboard!$F$6,Dashboard!$C$6,1),0)),"",DATE(Dashboard!$F$6,Dashboard!$C$6,7)) | B11: =IF($A11="","",SUMIFS(Transaksi!$C:$C,Transaksi!$A:$A,$A11,Transaksi!$B:$B,"Masuk")) | C11: =IF($A11="","",SUMIFS(Transaksi!$C:$C,Transaksi!$A:$A,$A11,Transaksi!$B:$B,"Keluar")) | D11: =IF($A11="","",$B11-$C11) | E11: =IF($A11="","",$E10+$D11) | F11: =IF(OR($A11="",$B11=0),"",REPT("█",MAX(1,ROUND(12*$B11/MAX($B$5:$B$35),0)))) | G11: =IF(OR($A11="",$C11=0),"",REPT("█",MAX(1,ROUND(12*$C11/MAX($C$5:$C$35),0)))) | H11: =IF($A11="","",DAY($A11))
A12: =IF(8>DAY(EOMONTH(DATE(Dashboard!$F$6,Dashboard!$C$6,1),0)),"",DATE(Dashboard!$F$6,Dashboard!$C$6,8)) | B12: =IF($A12="","",SUMIFS(Transaksi!$C:$C,Transaksi!$A:$A,$A12,Transaksi!$B:$B,"Masuk")) | C12: =IF($A12="","",SUMIFS(Transaksi!$C:$C,Transaksi!$A:$A,$A12,Transaksi!$B:$B,"Keluar")) | D12: =IF($A12="","",$B12-$C12) | E12: =IF($A12="","",$E11+$D12) | F12: =IF(OR($A12="",$B12=0),"",REPT("█",MAX(1,ROUND(12*$B12/MAX($B$5:$B$35),0)))) | G12: =IF(OR($A12="",$C12=0),"",REPT("█",MAX(1,ROUND(12*$C12/MAX($C$5:$C$35),0)))) | H12: =IF($A12="","",DAY($A12))
A13: =IF(9>DAY(EOMONTH(DATE(Dashboard!$F$6,Dashboard!$C$6,1),0)),"",DATE(Dashboard!$F$6,Dashboard!$C$6,9)) | B13: =IF($A13="","",SUMIFS(Transaksi!$C:$C,Transaksi!$A:$A,$A13,Transaksi!$B:$B,"Masuk")) | C13: =IF($A13="","",SUMIFS(Transaksi!$C:$C,Transaksi!$A:$A,$A13,Transaksi!$B:$B,"Keluar")) | D13: =IF($A13="","",$B13-$C13) | E13: =IF($A13="","",$E12+$D13) | F13: =IF(OR($A13="",$B13=0),"",REPT("█",MAX(1,ROUND(12*$B13/MAX($B$5:$B$35),0)))) | G13: =IF(OR($A13="",$C13=0),"",REPT("█",MAX(1,ROUND(12*$C13/MAX($C$5:$C$35),0)))) | H13: =IF($A13="","",DAY($A13))
A14: =IF(10>DAY(EOMONTH(DATE(Dashboard!$F$6,Dashboard!$C$6,1),0)),"",DATE(Dashboard!$F$6,Dashboard!$C$6,10)) | B14: =IF($A14="","",SUMIFS(Transaksi!$C:$C,Transaksi!$A:$A,$A14,Transaksi!$B:$B,"Masuk")) | C14: =IF($A14="","",SUMIFS(Transaksi!$C:$C,Transaksi!$A:$A,$A14,Transaksi!$B:$B,"Keluar")) | D14: =IF($A14="","",$B14-$C14) | E14: =IF($A14="","",$E13+$D14) | F14: =IF(OR($A14="",$B14=0),"",REPT("█",MAX(1,ROUND(12*$B14/MAX($B$5:$B$35),0)))) | G14: =IF(OR($A14="",$C14=0),"",REPT("█",MAX(1,ROUND(12*$C14/MAX($C$5:$C$35),0)))) | H14: =IF($A14="","",DAY($A14))
A15: =IF(11>DAY(EOMONTH(DATE(Dashboard!$F$6,Dashboard!$C$6,1),0)),"",DATE(Dashboard!$F$6,Dashboard!$C$6,11)) | B15: =IF($A15="","",SUMIFS(Transaksi!$C:$C,Transaksi!$A:$A,$A15,Transaksi!$B:$B,"Masuk")) | C15: =IF($A15="","",SUMIFS(Transaksi!$C:$C,Transaksi!$A:$A,$A15,Transaksi!$B:$B,"Keluar")) | D15: =IF($A15="","",$B15-$C15) | E15: =IF($A15="","",$E14+$D15) | F15: =IF(OR($A15="",$B15=0),"",REPT("█",MAX(1,ROUND(12*$B15/MAX($B$5:$B$35),0)))) | G15: =IF(OR($A15="",$C15=0),"",REPT("█",MAX(1,ROUND(12*$C15/MAX($C$5:$C$35),0)))) | H15: =IF($A15="","",DAY($A15))
A16: =IF(12>DAY(EOMONTH(DATE(Dashboard!$F$6,Dashboard!$C$6,1),0)),"",DATE(Dashboard!$F$6,Dashboard!$C$6,12)) | B16: =IF($A16="","",SUMIFS(Transaksi!$C:$C,Transaksi!$A:$A,$A16,Transaksi!$B:$B,"Masuk")) | C16: =IF($A16="","",SUMIFS(Transaksi!$C:$C,Transaksi!$A:$A,$A16,Transaksi!$B:$B,"Keluar")) | D16: =IF($A16="","",$B16-$C16) | E16: =IF($A16="","",$E15+$D16) | F16: =IF(OR($A16="",$B16=0),"",REPT("█",MAX(1,ROUND(12*$B16/MAX($B$5:$B$35),0)))) | G16: =IF(OR($A16="",$C16=0),"",REPT("█",MAX(1,ROUND(12*$C16/MAX($C$5:$C$35),0)))) | H16: =IF($A16="","",DAY($A16))
A17: =IF(13>DAY(EOMONTH(DATE(Dashboard!$F$6,Dashboard!$C$6,1),0)),"",DATE(Dashboard!$F$6,Dashboard!$C$6,13)) | B17: =IF($A17="","",SUMIFS(Transaksi!$C:$C,Transaksi!$A:$A,$A17,Transaksi!$B:$B,"Masuk")) | C17: =IF($A17="","",SUMIFS(Transaksi!$C:$C,Transaksi!$A:$A,$A17,Transaksi!$B:$B,"Keluar")) | D17: =IF($A17="","",$B17-$C17) | E17: =IF($A17="","",$E16+$D17) | F17: =IF(OR($A17="",$B17=0),"",REPT("█",MAX(1,ROUND(12*$B17/MAX($B$5:$B$35),0)))) | G17: =IF(OR($A17="",$C17=0),"",REPT("█",MAX(1,ROUND(12*$C17/MAX($C$5:$C$35),0)))) | H17: =IF($A17="","",DAY($A17))
A18: =IF(14>DAY(EOMONTH(DATE(Dashboard!$F$6,Dashboard!$C$6,1),0)),"",DATE(Dashboard!$F$6,Dashboard!$C$6,14)) | B18: =IF($A18="","",SUMIFS(Transaksi!$C:$C,Transaksi!$A:$A,$A18,Transaksi!$B:$B,"Masuk")) | C18: =IF($A18="","",SUMIFS(Transaksi!$C:$C,Transaksi!$A:$A,$A18,Transaksi!$B:$B,"Keluar")) | D18: =IF($A18="","",$B18-$C18) | E18: =IF($A18="","",$E17+$D18) | F18: =IF(OR($A18="",$B18=0),"",REPT("█",MAX(1,ROUND(12*$B18/MAX($B$5:$B$35),0)))) | G18: =IF(OR($A18="",$C18=0),"",REPT("█",MAX(1,ROUND(12*$C18/MAX($C$5:$C$35),0)))) | H18: =IF($A18="","",DAY($A18))
A19: =IF(15>DAY(EOMONTH(DATE(Dashboard!$F$6,Dashboard!$C$6,1),0)),"",DATE(Dashboard!$F$6,Dashboard!$C$6,15)) | B19: =IF($A19="","",SUMIFS(Transaksi!$C:$C,Transaksi!$A:$A,$A19,Transaksi!$B:$B,"Masuk")) | C19: =IF($A19="","",SUMIFS(Transaksi!$C:$C,Transaksi!$A:$A,$A19,Transaksi!$B:$B,"Keluar")) | D19: =IF($A19="","",$B19-$C19) | E19: =IF($A19="","",$E18+$D19) | F19: =IF(OR($A19="",$B19=0),"",REPT("█",MAX(1,ROUND(12*$B19/MAX($B$5:$B$35),0)))) | G19: =IF(OR($A19="",$C19=0),"",REPT("█",MAX(1,ROUND(12*$C19/MAX($C$5:$C$35),0)))) | H19: =IF($A19="","",DAY($A19))
A20: =IF(16>DAY(EOMONTH(DATE(Dashboard!$F$6,Dashboard!$C$6,1),0)),"",DATE(Dashboard!$F$6,Dashboard!$C$6,16)) | B20: =IF($A20="","",SUMIFS(Transaksi!$C:$C,Transaksi!$A:$A,$A20,Transaksi!$B:$B,"Masuk")) | C20: =IF($A20="","",SUMIFS(Transaksi!$C:$C,Transaksi!$A:$A,$A20,Transaksi!$B:$B,"Keluar")) | D20: =IF($A20="","",$B20-$C20) | E20: =IF($A20="","",$E19+$D20) | F20: =IF(OR($A20="",$B20=0),"",REPT("█",MAX(1,ROUND(12*$B20/MAX($B$5:$B$35),0)))) | G20: =IF(OR($A20="",$C20=0),"",REPT("█",MAX(1,ROUND(12*$C20/MAX($C$5:$C$35),0)))) | H20: =IF($A20="","",DAY($A20))
A21: =IF(17>DAY(EOMONTH(DATE(Dashboard!$F$6,Dashboard!$C$6,1),0)),"",DATE(Dashboard!$F$6,Dashboard!$C$6,17)) | B21: =IF($A21="","",SUMIFS(Transaksi!$C:$C,Transaksi!$A:$A,$A21,Transaksi!$B:$B,"Masuk")) | C21: =IF($A21="","",SUMIFS(Transaksi!$C:$C,Transaksi!$A:$A,$A21,Transaksi!$B:$B,"Keluar")) | D21: =IF($A21="","",$B21-$C21) | E21: =IF($A21="","",$E20+$D21) | F21: =IF(OR($A21="",$B21=0),"",REPT("█",MAX(1,ROUND(12*$B21/MAX($B$5:$B$35),0)))) | G21: =IF(OR($A21="",$C21=0),"",REPT("█",MAX(1,ROUND(12*$C21/MAX($C$5:$C$35),0)))) | H21: =IF($A21="","",DAY($A21))
A22: =IF(18>DAY(EOMONTH(DATE(Dashboard!$F$6,Dashboard!$C$6,1),0)),"",DATE(Dashboard!$F$6,Dashboard!$C$6,18)) | B22: =IF($A22="","",SUMIFS(Transaksi!$C:$C,Transaksi!$A:$A,$A22,Transaksi!$B:$B,"Masuk")) | C22: =IF($A22="","",SUMIFS(Transaksi!$C:$C,Transaksi!$A:$A,$A22,Transaksi!$B:$B,"Keluar")) | D22: =IF($A22="","",$B22-$C22) | E22: =IF($A22="","",$E21+$D22) | F22: =IF(OR($A22="",$B22=0),"",REPT("█",MAX(1,ROUND(12*$B22/MAX($B$5:$B$35),0)))) | G22: =IF(OR($A22="",$C22=0),"",REPT("█",MAX(1,ROUND(12*$C22/MAX($C$5:$C$35),0)))) | H22: =IF($A22="","",DAY($A22))
A23: =IF(19>DAY(EOMONTH(DATE(Dashboard!$F$6,Dashboard!$C$6,1),0)),"",DATE(Dashboard!$F$6,Dashboard!$C$6,19)) | B23: =IF($A23="","",SUMIFS(Transaksi!$C:$C,Transaksi!$A:$A,$A23,Transaksi!$B:$B,"Masuk")) | C23: =IF($A23="","",SUMIFS(Transaksi!$C:$C,Transaksi!$A:$A,$A23,Transaksi!$B:$B,"Keluar")) | D23: =IF($A23="","",$B23-$C23) | E23: =IF($A23="","",$E22+$D23) | F23: =IF(OR($A23="",$B23=0),"",REPT("█",MAX(1,ROUND(12*$B23/MAX($B$5:$B$35),0)))) | G23: =IF(OR($A23="",$C23=0),"",REPT("█",MAX(1,ROUND(12*$C23/MAX($C$5:$C$35),0)))) | H23: =IF($A23="","",DAY($A23))
A24: =IF(20>DAY(EOMONTH(DATE(Dashboard!$F$6,Dashboard!$C$6,1),0)),"",DATE(Dashboard!$F$6,Dashboard!$C$6,20)) | B24: =IF($A24="","",SUMIFS(Transaksi!$C:$C,Transaksi!$A:$A,$A24,Transaksi!$B:$B,"Masuk")) | C24: =IF($A24="","",SUMIFS(Transaksi!$C:$C,Transaksi!$A:$A,$A24,Transaksi!$B:$B,"Keluar")) | D24: =IF($A24="","",$B24-$C24) | E24: =IF($A24="","",$E23+$D24) | F24: =IF(OR($A24="",$B24=0),"",REPT("█",MAX(1,ROUND(12*$B24/MAX($B$5:$B$35),0)))) | G24: =IF(OR($A24="",$C24=0),"",REPT("█",MAX(1,ROUND(12*$C24/MAX($C$5:$C$35),0)))) | H24: =IF($A24="","",DAY($A24))
A25: =IF(21>DAY(EOMONTH(DATE(Dashboard!$F$6,Dashboard!$C$6,1),0)),"",DATE(Dashboard!$F$6,Dashboard!$C$6,21)) | B25: =IF($A25="","",SUMIFS(Transaksi!$C:$C,Transaksi!$A:$A,$A25,Transaksi!$B:$B,"Masuk")) | C25: =IF($A25="","",SUMIFS(Transaksi!$C:$C,Transaksi!$A:$A,$A25,Transaksi!$B:$B,"Keluar")) | D25: =IF($A25="","",$B25-$C25) | E25: =IF($A25="","",$E24+$D25) | F25: =IF(OR($A25="",$B25=0),"",REPT("█",MAX(1,ROUND(12*$B25/MAX($B$5:$B$35),0)))) | G25: =IF(OR($A25="",$C25=0),"",REPT("█",MAX(1,ROUND(12*$C25/MAX($C$5:$C$35),0)))) | H25: =IF($A25="","",DAY($A25))
A26: =IF(22>DAY(EOMONTH(DATE(Dashboard!$F$6,Dashboard!$C$6,1),0)),"",DATE(Dashboard!$F$6,Dashboard!$C$6,22)) | B26: =IF($A26="","",SUMIFS(Transaksi!$C:$C,Transaksi!$A:$A,$A26,Transaksi!$B:$B,"Masuk")) | C26: =IF($A26="","",SUMIFS(Transaksi!$C:$C,Transaksi!$A:$A,$A26,Transaksi!$B:$B,"Keluar")) | D26: =IF($A26="","",$B26-$C26) | E26: =IF($A26="","",$E25+$D26) | F26: =IF(OR($A26="",$B26=0),"",REPT("█",MAX(1,ROUND(12*$B26/MAX($B$5:$B$35),0)))) | G26: =IF(OR($A26="",$C26=0),"",REPT("█",MAX(1,ROUND(12*$C26/MAX($C$5:$C$35),0)))) | H26: =IF($A26="","",DAY($A26))
A27: =IF(23>DAY(EOMONTH(DATE(Dashboard!$F$6,Dashboard!$C$6,1),0)),"",DATE(Dashboard!$F$6,Dashboard!$C$6,23)) | B27: =IF($A27="","",SUMIFS(Transaksi!$C:$C,Transaksi!$A:$A,$A27,Transaksi!$B:$B,"Masuk")) | C27: =IF($A27="","",SUMIFS(Transaksi!$C:$C,Transaksi!$A:$A,$A27,Transaksi!$B:$B,"Keluar")) | D27: =IF($A27="","",$B27-$C27) | E27: =IF($A27="","",$E26+$D27) | F27: =IF(OR($A27="",$B27=0),"",REPT("█",MAX(1,ROUND(12*$B27/MAX($B$5:$B$35),0)))) | G27: =IF(OR($A27="",$C27=0),"",REPT("█",MAX(1,ROUND(12*$C27/MAX($C$5:$C$35),0)))) | H27: =IF($A27="","",DAY($A27))
A28: =IF(24>DAY(EOMONTH(DATE(Dashboard!$F$6,Dashboard!$C$6,1),0)),"",DATE(Dashboard!$F$6,Dashboard!$C$6,24)) | B28: =IF($A28="","",SUMIFS(Transaksi!$C:$C,Transaksi!$A:$A,$A28,Transaksi!$B:$B,"Masuk")) | C28: =IF($A28="","",SUMIFS(Transaksi!$C:$C,Transaksi!$A:$A,$A28,Transaksi!$B:$B,"Keluar")) | D28: =IF($A28="","",$B28-$C28) | E28: =IF($A28="","",$E27+$D28) | F28: =IF(OR($A28="",$B28=0),"",REPT("█",MAX(1,ROUND(12*$B28/MAX($B$5:$B$35),0)))) | G28: =IF(OR($A28="",$C28=0),"",REPT("█",MAX(1,ROUND(12*$C28/MAX($C$5:$C$35),0)))) | H28: =IF($A28="","",DAY($A28))
A29: =IF(25>DAY(EOMONTH(DATE(Dashboard!$F$6,Dashboard!$C$6,1),0)),"",DATE(Dashboard!$F$6,Dashboard!$C$6,25)) | B29: =IF($A29="","",SUMIFS(Transaksi!$C:$C,Transaksi!$A:$A,$A29,Transaksi!$B:$B,"Masuk")) | C29: =IF($A29="","",SUMIFS(Transaksi!$C:$C,Transaksi!$A:$A,$A29,Transaksi!$B:$B,"Keluar")) | D29: =IF($A29="","",$B29-$C29) | E29: =IF($A29="","",$E28+$D29) | F29: =IF(OR($A29="",$B29=0),"",REPT("█",MAX(1,ROUND(12*$B29/MAX($B$5:$B$35),0)))) | G29: =IF(OR($A29="",$C29=0),"",REPT("█",MAX(1,ROUND(12*$C29/MAX($C$5:$C$35),0)))) | H29: =IF($A29="","",DAY($A29))
A30: =IF(26>DAY(EOMONTH(DATE(Dashboard!$F$6,Dashboard!$C$6,1),0)),"",DATE(Dashboard!$F$6,Dashboard!$C$6,26)) | B30: =IF($A30="","",SUMIFS(Transaksi!$C:$C,Transaksi!$A:$A,$A30,Transaksi!$B:$B,"Masuk")) | C30: =IF($A30="","",SUMIFS(Transaksi!$C:$C,Transaksi!$A:$A,$A30,Transaksi!$B:$B,"Keluar")) | D30: =IF($A30="","",$B30-$C30) | E30: =IF($A30="","",$E29+$D30) | F30: =IF(OR($A30="",$B30=0),"",REPT("█",MAX(1,ROUND(12*$B30/MAX($B$5:$B$35),0)))) | G30: =IF(OR($A30="",$C30=0),"",REPT("█",MAX(1,ROUND(12*$C30/MAX($C$5:$C$35),0)))) | H30: =IF($A30="","",DAY($A30))
A31: =IF(27>DAY(EOMONTH(DATE(Dashboard!$F$6,Dashboard!$C$6,1),0)),"",DATE(Dashboard!$F$6,Dashboard!$C$6,27)) | B31: =IF($A31="","",SUMIFS(Transaksi!$C:$C,Transaksi!$A:$A,$A31,Transaksi!$B:$B,"Masuk")) | C31: =IF($A31="","",SUMIFS(Transaksi!$C:$C,Transaksi!$A:$A,$A31,Transaksi!$B:$B,"Keluar")) | D31: =IF($A31="","",$B31-$C31) | E31: =IF($A31="","",$E30+$D31) | F31: =IF(OR($A31="",$B31=0),"",REPT("█",MAX(1,ROUND(12*$B31/MAX($B$5:$B$35),0)))) | G31: =IF(OR($A31="",$C31=0),"",REPT("█",MAX(1,ROUND(12*$C31/MAX($C$5:$C$35),0)))) | H31: =IF($A31="","",DAY($A31))
A32: =IF(28>DAY(EOMONTH(DATE(Dashboard!$F$6,Dashboard!$C$6,1),0)),"",DATE(Dashboard!$F$6,Dashboard!$C$6,28)) | B32: =IF($A32="","",SUMIFS(Transaksi!$C:$C,Transaksi!$A:$A,$A32,Transaksi!$B:$B,"Masuk")) | C32: =IF($A32="","",SUMIFS(Transaksi!$C:$C,Transaksi!$A:$A,$A32,Transaksi!$B:$B,"Keluar")) | D32: =IF($A32="","",$B32-$C32) | E32: =IF($A32="","",$E31+$D32) | F32: =IF(OR($A32="",$B32=0),"",REPT("█",MAX(1,ROUND(12*$B32/MAX($B$5:$B$35),0)))) | G32: =IF(OR($A32="",$C32=0),"",REPT("█",MAX(1,ROUND(12*$C32/MAX($C$5:$C$35),0)))) | H32: =IF($A32="","",DAY($A32))
A33: =IF(29>DAY(EOMONTH(DATE(Dashboard!$F$6,Dashboard!$C$6,1),0)),"",DATE(Dashboard!$F$6,Dashboard!$C$6,29)) | B33: =IF($A33="","",SUMIFS(Transaksi!$C:$C,Transaksi!$A:$A,$A33,Transaksi!$B:$B,"Masuk")) | C33: =IF($A33="","",SUMIFS(Transaksi!$C:$C,Transaksi!$A:$A,$A33,Transaksi!$B:$B,"Keluar")) | D33: =IF($A33="","",$B33-$C33) | E33: =IF($A33="","",$E32+$D33) | F33: =IF(OR($A33="",$B33=0),"",REPT("█",MAX(1,ROUND(12*$B33/MAX($B$5:$B$35),0)))) | G33: =IF(OR($A33="",$C33=0),"",REPT("█",MAX(1,ROUND(12*$C33/MAX($C$5:$C$35),0)))) | H33: =IF($A33="","",DAY($A33))
A34: =IF(30>DAY(EOMONTH(DATE(Dashboard!$F$6,Dashboard!$C$6,1),0)),"",DATE(Dashboard!$F$6,Dashboard!$C$6,30)) | B34: =IF($A34="","",SUMIFS(Transaksi!$C:$C,Transaksi!$A:$A,$A34,Transaksi!$B:$B,"Masuk")) | C34: =IF($A34="","",SUMIFS(Transaksi!$C:$C,Transaksi!$A:$A,$A34,Transaksi!$B:$B,"Keluar")) | D34: =IF($A34="","",$B34-$C34) | E34: =IF($A34="","",$E33+$D34) | F34: =IF(OR($A34="",$B34=0),"",REPT("█",MAX(1,ROUND(12*$B34/MAX($B$5:$B$35),0)))) | G34: =IF(OR($A34="",$C34=0),"",REPT("█",MAX(1,ROUND(12*$C34/MAX($C$5:$C$35),0)))) | H34: =IF($A34="","",DAY($A34))
A35: =IF(31>DAY(EOMONTH(DATE(Dashboard!$F$6,Dashboard!$C$6,1),0)),"",DATE(Dashboard!$F$6,Dashboard!$C$6,31)) | B35: =IF($A35="","",SUMIFS(Transaksi!$C:$C,Transaksi!$A:$A,$A35,Transaksi!$B:$B,"Masuk")) | C35: =IF($A35="","",SUMIFS(Transaksi!$C:$C,Transaksi!$A:$A,$A35,Transaksi!$B:$B,"Keluar")) | D35: =IF($A35="","",$B35-$C35) | E35: =IF($A35="","",$E34+$D35) | F35: =IF(OR($A35="",$B35=0),"",REPT("█",MAX(1,ROUND(12*$B35/MAX($B$5:$B$35),0)))) | G35: =IF(OR($A35="",$C35=0),"",REPT("█",MAX(1,ROUND(12*$C35/MAX($C$5:$C$35),0)))) | H35: =IF($A35="","",DAY($A35))
A37: TOTAL BULAN | B37: =SUM(B5:B35) | C37: =SUM(C5:C35) | D37: =SUM(D5:D35)
A39: Baris merah pada Saldo Berjalan = kas minus pada hari itu. Kolom Grafik memakai balok █ supaya tetap terbaca di HP.

Sheet Kategori
B2: KASUMKM · DAFTAR PILIHAN
B3: Kategori & Dropdown
B4: Boleh ditambah atau diubah sesuai jenis usaha. Isi tanpa baris kosong di tengah.
B6: Kategori Pemasukan | C6: Kategori Pengeluaran | D6: Metode Bayar | E6: Status | F6: Jenis | G6: Semua Kategori (bantu)
B7: Penjualan Tunai | C7: Bahan Baku | D7: Tunai | E7: Belum Ditinjau | F7: Masuk | G7: Penjualan Tunai
B8: Penjualan Online | C8: Barang Dagang | D8: Transfer Bank | E8: Disetujui | F8: Keluar | G8: Penjualan Online
B9: Pendapatan Jasa | C9: Gaji & Upah | D9: QRIS | E9: Perlu Perbaikan | G9: Pendapatan Jasa
B10: Titipan/Konsinyasi | C10: Sewa Tempat | D10: E-wallet | G10: Titipan/Konsinyasi
B11: Pendapatan Lain-lain | C11: Listrik & Air | D11: Lainnya | G11: Pendapatan Lain-lain
C12: Transport & Kirim | G12: Bahan Baku
C13: Kemasan | G13: Barang Dagang
C14: Pulsa & Internet | G14: Gaji & Upah
C15: Peralatan | G15: Sewa Tempat
C16: Promosi | G16: Listrik & Air
C17: Pajak & Retribusi | G17: Transport & Kirim
C18: Pengeluaran Lain-lain | G18: Kemasan
G19: Pulsa & Internet
G20: Peralatan
G21: Promosi
G22: Pajak & Retribusi
G23: Pengeluaran Lain-lain
B44: Setelah menambah kategori baru, salin juga ke kolom 'Semua Kategori (bantu)' agar muncul di dropdown sheet Transaksi.

Sheet Cek Data
B2: KASUMKM · KUALITAS DATA
B3: Cek Data
B4: Pakai Filter pada kolom Masalah → hilangkan centang (Kosong) untuk melihat hanya baris yang perlu diperbaiki.
B6: RINGKASAN
B7: Baris tanpa kategori | C7: =COUNTIFS(Transaksi!$A$2:$A$501,"<>",Transaksi!$E$2:$E$501,"")
B8: Baris tanpa nominal | C8: =COUNTIFS(Transaksi!$A$2:$A$501,"<>",Transaksi!$C$2:$C$501,"")
B9: Baris belum disetujui | C9: =COUNTIFS(Transaksi!$A$2:$A$501,"<>",Transaksi!$G$2:$G$501,"<>Disetujui")
B10: Total baris terisi | C10: =COUNTA(Transaksi!$A$2:$A$501)
B12: Baris di Transaksi | C12: Tanggal | D12: Nominal | E12: Keterangan | F12: Masalah
B13: =IF(Transaksi!$A2="","",2) | C13: =IF(Transaksi!$A2="","",Transaksi!$A2) | D13: =IF(Transaksi!$A2="","",Transaksi!$C2) | E13: =IF(Transaksi!$A2="","",Transaksi!$D2) | F13: =IF(Transaksi!$A2="","",TRIM(IF(Transaksi!$C2="","Nominal kosong. ","")&IF(N(Transaksi!$C2)<0,"Nominal negatif. ","")&IF(Transaksi!$B2="","Jenis belum diisi. ","")&IF(Transaksi!$E2="","Kategori belum diisi. ","")&IF(Transaksi!$A2>TODAY(),"Tanggal di masa depan. ","")&IF(COUNTIFS(Transaksi!$A$2:$A$501,Transaksi!$A2,Transaksi!$C$2:$C$501,Transaksi!$C2,Transaksi!$D$2:$D$501,Transaksi!$D2)>1,"Kemungkinan duplikat. ","")))
B14: =IF(Transaksi!$A3="","",3) | C14: =IF(Transaksi!$A3="","",Transaksi!$A3) | D14: =IF(Transaksi!$A3="","",Transaksi!$C3) | E14: =IF(Transaksi!$A3="","",Transaksi!$D3) | F14: =IF(Transaksi!$A3="","",TRIM(IF(Transaksi!$C3="","Nominal kosong. ","")&IF(N(Transaksi!$C3)<0,"Nominal negatif. ","")&IF(Transaksi!$B3="","Jenis belum diisi. ","")&IF(Transaksi!$E3="","Kategori belum diisi. ","")&IF(Transaksi!$A3>TODAY(),"Tanggal di masa depan. ","")&IF(COUNTIFS(Transaksi!$A$2:$A$501,Transaksi!$A3,Transaksi!$C$2:$C$501,Transaksi!$C3,Transaksi!$D$2:$D$501,Transaksi!$D3)>1,"Kemungkinan duplikat. ","")))
B15: =IF(Transaksi!$A4="","",4) | C15: =IF(Transaksi!$A4="","",Transaksi!$A4) | D15: =IF(Transaksi!$A4="","",Transaksi!$C4) | E15: =IF(Transaksi!$A4="","",Transaksi!$D4) | F15: =IF(Transaksi!$A4="","",TRIM(IF(Transaksi!$C4="","Nominal kosong. ","")&IF(N(Transaksi!$C4)<0,"Nominal negatif. ","")&IF(Transaksi!$B4="","Jenis belum diisi. ","")&IF(Transaksi!$E4="","Kategori belum diisi. ","")&IF(Transaksi!$A4>TODAY(),"Tanggal di masa depan. ","")&IF(COUNTIFS(Transaksi!$A$2:$A$501,Transaksi!$A4,Transaksi!$C$2:$C$501,Transaksi!$C4,Transaksi!$D$2:$D$501,Transaksi!$D4)>1,"Kemungkinan duplikat. ","")))
B16: =IF(Transaksi!$A5="","",5) | C16: =IF(Transaksi!$A5="","",Transaksi!$A5) | D16: =IF(Transaksi!$A5="","",Transaksi!$C5) | E16: =IF(Transaksi!$A5="","",Transaksi!$D5) | F16: =IF(Transaksi!$A5="","",TRIM(IF(Transaksi!$C5="","Nominal kosong. ","")&IF(N(Transaksi!$C5)<0,"Nominal negatif. ","")&IF(Transaksi!$B5="","Jenis belum diisi. ","")&IF(Transaksi!$E5="","Kategori belum diisi. ","")&IF(Transaksi!$A5>TODAY(),"Tanggal di masa depan. ","")&IF(COUNTIFS(Transaksi!$A$2:$A$501,Transaksi!$A5,Transaksi!$C$2:$C$501,Transaksi!$C5,Transaksi!$D$2:$D$501,Transaksi!$D5)>1,"Kemungkinan duplikat. ","")))
B17: =IF(Transaksi!$A6="","",6) | C17: =IF(Transaksi!$A6="","",Transaksi!$A6) | D17: =IF(Transaksi!$A6="","",Transaksi!$C6) | E17: =IF(Transaksi!$A6="","",Transaksi!$D6) | F17: =IF(Transaksi!$A6="","",TRIM(IF(Transaksi!$C6="","Nominal kosong. ","")&IF(N(Transaksi!$C6)<0,"Nominal negatif. ","")&IF(Transaksi!$B6="","Jenis belum diisi. ","")&IF(Transaksi!$E6="","Kategori belum diisi. ","")&IF(Transaksi!$A6>TODAY(),"Tanggal di masa depan. ","")&IF(COUNTIFS(Transaksi!$A$2:$A$501,Transaksi!$A6,Transaksi!$C$2:$C$501,Transaksi!$C6,Transaksi!$D$2:$D$501,Transaksi!$D6)>1,"Kemungkinan duplikat. ","")))
B18: =IF(Transaksi!$A7="","",7) | C18: =IF(Transaksi!$A7="","",Transaksi!$A7) | D18: =IF(Transaksi!$A7="","",Transaksi!$C7) | E18: =IF(Transaksi!$A7="","",Transaksi!$D7) | F18: =IF(Transaksi!$A7="","",TRIM(IF(Transaksi!$C7="","Nominal kosong. ","")&IF(N(Transaksi!$C7)<0,"Nominal negatif. ","")&IF(Transaksi!$B7="","Jenis belum diisi. ","")&IF(Transaksi!$E7="","Kategori belum diisi. ","")&IF(Transaksi!$A7>TODAY(),"Tanggal di masa depan. ","")&IF(COUNTIFS(Transaksi!$A$2:$A$501,Transaksi!$A7,Transaksi!$C$2:$C$501,Transaksi!$C7,Transaksi!$D$2:$D$501,Transaksi!$D7)>1,"Kemungkinan duplikat. ","")))
B19: =IF(Transaksi!$A8="","",8) | C19: =IF(Transaksi!$A8="","",Transaksi!$A8) | D19: =IF(Transaksi!$A8="","",Transaksi!$C8) | E19: =IF(Transaksi!$A8="","",Transaksi!$D8) | F19: =IF(Transaksi!$A8="","",TRIM(IF(Transaksi!$C8="","Nominal kosong. ","")&IF(N(Transaksi!$C8)<0,"Nominal negatif. ","")&IF(Transaksi!$B8="","Jenis belum diisi. ","")&IF(Transaksi!$E8="","Kategori belum diisi. ","")&IF(Transaksi!$A8>TODAY(),"Tanggal di masa depan. ","")&IF(COUNTIFS(Transaksi!$A$2:$A$501,Transaksi!$A8,Transaksi!$C$2:$C$501,Transaksi!$C8,Transaksi!$D$2:$D$501,Transaksi!$D8)>1,"Kemungkinan duplikat. ","")))
B20: =IF(Transaksi!$A9="","",9) | C20: =IF(Transaksi!$A9="","",Transaksi!$A9) | D20: =IF(Transaksi!$A9="","",Transaksi!$C9) | E20: =IF(Transaksi!$A9="","",Transaksi!$D9) | F20: =IF(Transaksi!$A9="","",TRIM(IF(Transaksi!$C9="","Nominal kosong. ","")&IF(N(Transaksi!$C9)<0,"Nominal negatif. ","")&IF(Transaksi!$B9="","Jenis belum diisi. ","")&IF(Transaksi!$E9="","Kategori belum diisi. ","")&IF(Transaksi!$A9>TODAY(),"Tanggal di masa depan. ","")&IF(COUNTIFS(Transaksi!$A$2:$A$501,Transaksi!$A9,Transaksi!$C$2:$C$501,Transaksi!$C9,Transaksi!$D$2:$D$501,Transaksi!$D9)>1,"Kemungkinan duplikat. ","")))
B21: =IF(Transaksi!$A10="","",10) | C21: =IF(Transaksi!$A10="","",Transaksi!$A10) | D21: =IF(Transaksi!$A10="","",Transaksi!$C10) | E21: =IF(Transaksi!$A10="","",Transaksi!$D10) | F21: =IF(Transaksi!$A10="","",TRIM(IF(Transaksi!$C10="","Nominal kosong. ","")&IF(N(Transaksi!$C10)<0,"Nominal negatif. ","")&IF(Transaksi!$B10="","Jenis belum diisi. ","")&IF(Transaksi!$E10="","Kategori belum diisi. ","")&IF(Transaksi!$A10>TODAY(),"Tanggal di masa depan. ","")&IF(COUNTIFS(Transaksi!$A$2:$A$501,Transaksi!$A10,Transaksi!$C$2:$C$501,Transaksi!$C10,Transaksi!$D$2:$D$501,Transaksi!$D10)>1,"Kemungkinan duplikat. ","")))
B22: =IF(Transaksi!$A11="","",11) | C22: =IF(Transaksi!$A11="","",Transaksi!$A11) | D22: =IF(Transaksi!$A11="","",Transaksi!$C11) | E22: =IF(Transaksi!$A11="","",Transaksi!$D11) | F22: =IF(Transaksi!$A11="","",TRIM(IF(Transaksi!$C11="","Nominal kosong. ","")&IF(N(Transaksi!$C11)<0,"Nominal negatif. ","")&IF(Transaksi!$B11="","Jenis belum diisi. ","")&IF(Transaksi!$E11="","Kategori belum diisi. ","")&IF(Transaksi!$A11>TODAY(),"Tanggal di masa depan. ","")&IF(COUNTIFS(Transaksi!$A$2:$A$501,Transaksi!$A11,Transaksi!$C$2:$C$501,Transaksi!$C11,Transaksi!$D$2:$D$501,Transaksi!$D11)>1,"Kemungkinan duplikat. ","")))
B23: =IF(Transaksi!$A12="","",12) | C23: =IF(Transaksi!$A12="","",Transaksi!$A12) | D23: =IF(Transaksi!$A12="","",Transaksi!$C12) | E23: =IF(Transaksi!$A12="","",Transaksi!$D12) | F23: =IF(Transaksi!$A12="","",TRIM(IF(Transaksi!$C12="","Nominal kosong. ","")&IF(N(Transaksi!$C12)<0,"Nominal negatif. ","")&IF(Transaksi!$B12="","Jenis belum diisi. ","")&IF(Transaksi!$E12="","Kategori belum diisi. ","")&IF(Transaksi!$A12>TODAY(),"Tanggal di masa depan. ","")&IF(COUNTIFS(Transaksi!$A$2:$A$501,Transaksi!$A12,Transaksi!$C$2:$C$501,Transaksi!$C12,Transaksi!$D$2:$D$501,Transaksi!$D12)>1,"Kemungkinan duplikat. ","")))
B24: =IF(Transaksi!$A13="","",13) | C24: =IF(Transaksi!$A13="","",Transaksi!$A13) | D24: =IF(Transaksi!$A13="","",Transaksi!$C13) | E24: =IF(Transaksi!$A13="","",Transaksi!$D13) | F24: =IF(Transaksi!$A13="","",TRIM(IF(Transaksi!$C13="","Nominal kosong. ","")&IF(N(Transaksi!$C13)<0,"Nominal negatif. ","")&IF(Transaksi!$B13="","Jenis belum diisi. ","")&IF(Transaksi!$E13="","Kategori belum diisi. ","")&IF(Transaksi!$A13>TODAY(),"Tanggal di masa depan. ","")&IF(COUNTIFS(Transaksi!$A$2:$A$501,Transaksi!$A13,Transaksi!$C$2:$C$501,Transaksi!$C13,Transaksi!$D$2:$D$501,Transaksi!$D13)>1,"Kemungkinan duplikat. ","")))
B25: =IF(Transaksi!$A14="","",14) | C25: =IF(Transaksi!$A14="","",Transaksi!$A14) | D25: =IF(Transaksi!$A14="","",Transaksi!$C14) | E25: =IF(Transaksi!$A14="","",Transaksi!$D14) | F25: =IF(Transaksi!$A14="","",TRIM(IF(Transaksi!$C14="","Nominal kosong. ","")&IF(N(Transaksi!$C14)<0,"Nominal negatif. ","")&IF(Transaksi!$B14="","Jenis belum diisi. ","")&IF(Transaksi!$E14="","Kategori belum diisi. ","")&IF(Transaksi!$A14>TODAY(),"Tanggal di masa depan. ","")&IF(COUNTIFS(Transaksi!$A$2:$A$501,Transaksi!$A14,Transaksi!$C$2:$C$501,Transaksi!$C14,Transaksi!$D$2:$D$501,Transaksi!$D14)>1,"Kemungkinan duplikat. ","")))
B26: =IF(Transaksi!$A15="","",15) | C26: =IF(Transaksi!$A15="","",Transaksi!$A15) | D26: =IF(Transaksi!$A15="","",Transaksi!$C15) | E26: =IF(Transaksi!$A15="","",Transaksi!$D15) | F26: =IF(Transaksi!$A15="","",TRIM(IF(Transaksi!$C15="","Nominal kosong. ","")&IF(N(Transaksi!$C15)<0,"Nominal negatif. ","")&IF(Transaksi!$B15="","Jenis belum diisi. ","")&IF(Transaksi!$E15="","Kategori belum diisi. ","")&IF(Transaksi!$A15>TODAY(),"Tanggal di masa depan. ","")&IF(COUNTIFS(Transaksi!$A$2:$A$501,Transaksi!$A15,Transaksi!$C$2:$C$501,Transaksi!$C15,Transaksi!$D$2:$D$501,Transaksi!$D15)>1,"Kemungkinan duplikat. ","")))
B27: =IF(Transaksi!$A16="","",16) | C27: =IF(Transaksi!$A16="","",Transaksi!$A16) | D27: =IF(Transaksi!$A16="","",Transaksi!$C16) | E27: =IF(Transaksi!$A16="","",Transaksi!$D16) | F27: =IF(Transaksi!$A16="","",TRIM(IF(Transaksi!$C16="","Nominal kosong. ","")&IF(N(Transaksi!$C16)<0,"Nominal negatif. ","")&IF(Transaksi!$B16="","Jenis belum diisi. ","")&IF(Transaksi!$E16="","Kategori belum diisi. ","")&IF(Transaksi!$A16>TODAY(),"Tanggal di masa depan. ","")&IF(COUNTIFS(Transaksi!$A$2:$A$501,Transaksi!$A16,Transaksi!$C$2:$C$501,Transaksi!$C16,Transaksi!$D$2:$D$501,Transaksi!$D16)>1,"Kemungkinan duplikat. ","")))
B28: =IF(Transaksi!$A17="","",17) | C28: =IF(Transaksi!$A17="","",Transaksi!$A17) | D28: =IF(Transaksi!$A17="","",Transaksi!$C17) | E28: =IF(Transaksi!$A17="","",Transaksi!$D17) | F28: =IF(Transaksi!$A17="","",TRIM(IF(Transaksi!$C17="","Nominal kosong. ","")&IF(N(Transaksi!$C17)<0,"Nominal negatif. ","")&IF(Transaksi!$B17="","Jenis belum diisi. ","")&IF(Transaksi!$E17="","Kategori belum diisi. ","")&IF(Transaksi!$A17>TODAY(),"Tanggal di masa depan. ","")&IF(COUNTIFS(Transaksi!$A$2:$A$501,Transaksi!$A17,Transaksi!$C$2:$C$501,Transaksi!$C17,Transaksi!$D$2:$D$501,Transaksi!$D17)>1,"Kemungkinan duplikat. ","")))
B29: =IF(Transaksi!$A18="","",18) | C29: =IF(Transaksi!$A18="","",Transaksi!$A18) | D29: =IF(Transaksi!$A18="","",Transaksi!$C18) | E29: =IF(Transaksi!$A18="","",Transaksi!$D18) | F29: =IF(Transaksi!$A18="","",TRIM(IF(Transaksi!$C18="","Nominal kosong. ","")&IF(N(Transaksi!$C18)<0,"Nominal negatif. ","")&IF(Transaksi!$B18="","Jenis belum diisi. ","")&IF(Transaksi!$E18="","Kategori belum diisi. ","")&IF(Transaksi!$A18>TODAY(),"Tanggal di masa depan. ","")&IF(COUNTIFS(Transaksi!$A$2:$A$501,Transaksi!$A18,Transaksi!$C$2:$C$501,Transaksi!$C18,Transaksi!$D$2:$D$501,Transaksi!$D18)>1,"Kemungkinan duplikat. ","")))
B30: =IF(Transaksi!$A19="","",19) | C30: =IF(Transaksi!$A19="","",Transaksi!$A19) | D30: =IF(Transaksi!$A19="","",Transaksi!$C19) | E30: =IF(Transaksi!$A19="","",Transaksi!$D19) | F30: =IF(Transaksi!$A19="","",TRIM(IF(Transaksi!$C19="","Nominal kosong. ","")&IF(N(Transaksi!$C19)<0,"Nominal negatif. ","")&IF(Transaksi!$B19="","Jenis belum diisi. ","")&IF(Transaksi!$E19="","Kategori belum diisi. ","")&IF(Transaksi!$A19>TODAY(),"Tanggal di masa depan. ","")&IF(COUNTIFS(Transaksi!$A$2:$A$501,Transaksi!$A19,Transaksi!$C$2:$C$501,Transaksi!$C19,Transaksi!$D$2:$D$501,Transaksi!$D19)>1,"Kemungkinan duplikat. ","")))
B31: =IF(Transaksi!$A20="","",20) | C31: =IF(Transaksi!$A20="","",Transaksi!$A20) | D31: =IF(Transaksi!$A20="","",Transaksi!$C20) | E31: =IF(Transaksi!$A20="","",Transaksi!$D20) | F31: =IF(Transaksi!$A20="","",TRIM(IF(Transaksi!$C20="","Nominal kosong. ","")&IF(N(Transaksi!$C20)<0,"Nominal negatif. ","")&IF(Transaksi!$B20="","Jenis belum diisi. ","")&IF(Transaksi!$E20="","Kategori belum diisi. ","")&IF(Transaksi!$A20>TODAY(),"Tanggal di masa depan. ","")&IF(COUNTIFS(Transaksi!$A$2:$A$501,Transaksi!$A20,Transaksi!$C$2:$C$501,Transaksi!$C20,Transaksi!$D$2:$D$501,Transaksi!$D20)>1,"Kemungkinan duplikat. ","")))
B32: =IF(Transaksi!$A21="","",21) | C32: =IF(Transaksi!$A21="","",Transaksi!$A21) | D32: =IF(Transaksi!$A21="","",Transaksi!$C21) | E32: =IF(Transaksi!$A21="","",Transaksi!$D21) | F32: =IF(Transaksi!$A21="","",TRIM(IF(Transaksi!$C21="","Nominal kosong. ","")&IF(N(Transaksi!$C21)<0,"Nominal negatif. ","")&IF(Transaksi!$B21="","Jenis belum diisi. ","")&IF(Transaksi!$E21="","Kategori belum diisi. ","")&IF(Transaksi!$A21>TODAY(),"Tanggal di masa depan. ","")&IF(COUNTIFS(Transaksi!$A$2:$A$501,Transaksi!$A21,Transaksi!$C$2:$C$501,Transaksi!$C21,Transaksi!$D$2:$D$501,Transaksi!$D21)>1,"Kemungkinan duplikat. ","")))
B33: =IF(Transaksi!$A22="","",22) | C33: =IF(Transaksi!$A22="","",Transaksi!$A22) | D33: =IF(Transaksi!$A22="","",Transaksi!$C22) | E33: =IF(Transaksi!$A22="","",Transaksi!$D22) | F33: =IF(Transaksi!$A22="","",TRIM(IF(Transaksi!$C22="","Nominal kosong. ","")&IF(N(Transaksi!$C22)<0,"Nominal negatif. ","")&IF(Transaksi!$B22="","Jenis belum diisi. ","")&IF(Transaksi!$E22="","Kategori belum diisi. ","")&IF(Transaksi!$A22>TODAY(),"Tanggal di masa depan. ","")&IF(COUNTIFS(Transaksi!$A$2:$A$501,Transaksi!$A22,Transaksi!$C$2:$C$501,Transaksi!$C22,Transaksi!$D$2:$D$501,Transaksi!$D22)>1,"Kemungkinan duplikat. ","")))
B34: =IF(Transaksi!$A23="","",23) | C34: =IF(Transaksi!$A23="","",Transaksi!$A23) | D34: =IF(Transaksi!$A23="","",Transaksi!$C23) | E34: =IF(Transaksi!$A23="","",Transaksi!$D23) | F34: =IF(Transaksi!$A23="","",TRIM(IF(Transaksi!$C23="","Nominal kosong. ","")&IF(N(Transaksi!$C23)<0,"Nominal negatif. ","")&IF(Transaksi!$B23="","Jenis belum diisi. ","")&IF(Transaksi!$E23="","Kategori belum diisi. ","")&IF(Transaksi!$A23>TODAY(),"Tanggal di masa depan. ","")&IF(COUNTIFS(Transaksi!$A$2:$A$501,Transaksi!$A23,Transaksi!$C$2:$C$501,Transaksi!$C23,Transaksi!$D$2:$D$501,Transaksi!$D23)>1,"Kemungkinan duplikat. ","")))
B35: =IF(Transaksi!$A24="","",24) | C35: =IF(Transaksi!$A24="","",Transaksi!$A24) | D35: =IF(Transaksi!$A24="","",Transaksi!$C24) | E35: =IF(Transaksi!$A24="","",Transaksi!$D24) | F35: =IF(Transaksi!$A24="","",TRIM(IF(Transaksi!$C24="","Nominal kosong. ","")&IF(N(Transaksi!$C24)<0,"Nominal negatif. ","")&IF(Transaksi!$B24="","Jenis belum diisi. ","")&IF(Transaksi!$E24="","Kategori belum diisi. ","")&IF(Transaksi!$A24>TODAY(),"Tanggal di masa depan. ","")&IF(COUNTIFS(Transaksi!$A$2:$A$501,Transaksi!$A24,Transaksi!$C$2:$C$501,Transaksi!$C24,Transaksi!$D$2:$D$501,Transaksi!$D24)>1,"Kemungkinan duplikat. ","")))
B36: =IF(Transaksi!$A25="","",25) | C36: =IF(Transaksi!$A25="","",Transaksi!$A25) | D36: =IF(Transaksi!$A25="","",Transaksi!$C25) | E36: =IF(Transaksi!$A25="","",Transaksi!$D25) | F36: =IF(Transaksi!$A25="","",TRIM(IF(Transaksi!$C25="","Nominal kosong. ","")&IF(N(Transaksi!$C25)<0,"Nominal negatif. ","")&IF(Transaksi!$B25="","Jenis belum diisi. ","")&IF(Transaksi!$E25="","Kategori belum diisi. ","")&IF(Transaksi!$A25>TODAY(),"Tanggal di masa depan. ","")&IF(COUNTIFS(Transaksi!$A$2:$A$501,Transaksi!$A25,Transaksi!$C$2:$C$501,Transaksi!$C25,Transaksi!$D$2:$D$501,Transaksi!$D25)>1,"Kemungkinan duplikat. ","")))
B37: =IF(Transaksi!$A26="","",26) | C37: =IF(Transaksi!$A26="","",Transaksi!$A26) | D37: =IF(Transaksi!$A26="","",Transaksi!$C26) | E37: =IF(Transaksi!$A26="","",Transaksi!$D26) | F37: =IF(Transaksi!$A26="","",TRIM(IF(Transaksi!$C26="","Nominal kosong. ","")&IF(N(Transaksi!$C26)<0,"Nominal negatif. ","")&IF(Transaksi!$B26="","Jenis belum diisi. ","")&IF(Transaksi!$E26="","Kategori belum diisi. ","")&IF(Transaksi!$A26>TODAY(),"Tanggal di masa depan. ","")&IF(COUNTIFS(Transaksi!$A$2:$A$501,Transaksi!$A26,Transaksi!$C$2:$C$501,Transaksi!$C26,Transaksi!$D$2:$D$501,Transaksi!$D26)>1,"Kemungkinan duplikat. ","")))
B38: =IF(Transaksi!$A27="","",27) | C38: =IF(Transaksi!$A27="","",Transaksi!$A27) | D38: =IF(Transaksi!$A27="","",Transaksi!$C27) | E38: =IF(Transaksi!$A27="","",Transaksi!$D27) | F38: =IF(Transaksi!$A27="","",TRIM(IF(Transaksi!$C27="","Nominal kosong. ","")&IF(N(Transaksi!$C27)<0,"Nominal negatif. ","")&IF(Transaksi!$B27="","Jenis belum diisi. ","")&IF(Transaksi!$E27="","Kategori belum diisi. ","")&IF(Transaksi!$A27>TODAY(),"Tanggal di masa depan. ","")&IF(COUNTIFS(Transaksi!$A$2:$A$501,Transaksi!$A27,Transaksi!$C$2:$C$501,Transaksi!$C27,Transaksi!$D$2:$D$501,Transaksi!$D27)>1,"Kemungkinan duplikat. ","")))
B39: =IF(Transaksi!$A28="","",28) | C39: =IF(Transaksi!$A28="","",Transaksi!$A28) | D39: =IF(Transaksi!$A28="","",Transaksi!$C28) | E39: =IF(Transaksi!$A28="","",Transaksi!$D28) | F39: =IF(Transaksi!$A28="","",TRIM(IF(Transaksi!$C28="","Nominal kosong. ","")&IF(N(Transaksi!$C28)<0,"Nominal negatif. ","")&IF(Transaksi!$B28="","Jenis belum diisi. ","")&IF(Transaksi!$E28="","Kategori belum diisi. ","")&IF(Transaksi!$A28>TODAY(),"Tanggal di masa depan. ","")&IF(COUNTIFS(Transaksi!$A$2:$A$501,Transaksi!$A28,Transaksi!$C$2:$C$501,Transaksi!$C28,Transaksi!$D$2:$D$501,Transaksi!$D28)>1,"Kemungkinan duplikat. ","")))
B40: =IF(Transaksi!$A29="","",29) | C40: =IF(Transaksi!$A29="","",Transaksi!$A29) | D40: =IF(Transaksi!$A29="","",Transaksi!$C29) | E40: =IF(Transaksi!$A29="","",Transaksi!$D29) | F40: =IF(Transaksi!$A29="","",TRIM(IF(Transaksi!$C29="","Nominal kosong. ","")&IF(N(Transaksi!$C29)<0,"Nominal negatif. ","")&IF(Transaksi!$B29="","Jenis belum diisi. ","")&IF(Transaksi!$E29="","Kategori belum diisi. ","")&IF(Transaksi!$A29>TODAY(),"Tanggal di masa depan. ","")&IF(COUNTIFS(Transaksi!$A$2:$A$501,Transaksi!$A29,Transaksi!$C$2:$C$501,Transaksi!$C29,Transaksi!$D$2:$D$501,Transaksi!$D29)>1,"Kemungkinan duplikat. ","")))
B41: =IF(Transaksi!$A30="","",30) | C41: =IF(Transaksi!$A30="","",Transaksi!$A30) | D41: =IF(Transaksi!$A30="","",Transaksi!$C30) | E41: =IF(Transaksi!$A30="","",Transaksi!$D30) | F41: =IF(Transaksi!$A30="","",TRIM(IF(Transaksi!$C30="","Nominal kosong. ","")&IF(N(Transaksi!$C30)<0,"Nominal negatif. ","")&IF(Transaksi!$B30="","Jenis belum diisi. ","")&IF(Transaksi!$E30="","Kategori belum diisi. ","")&IF(Transaksi!$A30>TODAY(),"Tanggal di masa depan. ","")&IF(COUNTIFS(Transaksi!$A$2:$A$501,Transaksi!$A30,Transaksi!$C$2:$C$501,Transaksi!$C30,Transaksi!$D$2:$D$501,Transaksi!$D30)>1,"Kemungkinan duplikat. ","")))
B42: =IF(Transaksi!$A31="","",31) | C42: =IF(Transaksi!$A31="","",Transaksi!$A31) | D42: =IF(Transaksi!$A31="","",Transaksi!$C31) | E42: =IF(Transaksi!$A31="","",Transaksi!$D31) | F42: =IF(Transaksi!$A31="","",TRIM(IF(Transaksi!$C31="","Nominal kosong. ","")&IF(N(Transaksi!$C31)<0,"Nominal negatif. ","")&IF(Transaksi!$B31="","Jenis belum diisi. ","")&IF(Transaksi!$E31="","Kategori belum diisi. ","")&IF(Transaksi!$A31>TODAY(),"Tanggal di masa depan. ","")&IF(COUNTIFS(Transaksi!$A$2:$A$501,Transaksi!$A31,Transaksi!$C$2:$C$501,Transaksi!$C31,Transaksi!$D$2:$D$501,Transaksi!$D31)>1,"Kemungkinan duplikat. ","")))
B43: =IF(Transaksi!$A32="","",32) | C43: =IF(Transaksi!$A32="","",Transaksi!$A32) | D43: =IF(Transaksi!$A32="","",Transaksi!$C32) | E43: =IF(Transaksi!$A32="","",Transaksi!$D32) | F43: =IF(Transaksi!$A32="","",TRIM(IF(Transaksi!$C32="","Nominal kosong. ","")&IF(N(Transaksi!$C32)<0,"Nominal negatif. ","")&IF(Transaksi!$B32="","Jenis belum diisi. ","")&IF(Transaksi!$E32="","Kategori belum diisi. ","")&IF(Transaksi!$A32>TODAY(),"Tanggal di masa depan. ","")&IF(COUNTIFS(Transaksi!$A$2:$A$501,Transaksi!$A32,Transaksi!$C$2:$C$501,Transaksi!$C32,Transaksi!$D$2:$D$501,Transaksi!$D32)>1,"Kemungkinan duplikat. ","")))
...

Sheet Contoh Pengisian
B2: KASUMKM · CONTOH
B3: Contoh Pengisian
B4: Hanya contoh. Sheet ini boleh dihapus.
B6: Tanggal | C6: Jenis | D6: Nominal (Rp) | E6: Keterangan | F6: Kategori (oleh admin) | G6: Status
B7: 46174 | C7: Masuk | D7: 450000 | E7: penjualan hari ini | F7: Penjualan Tunai | G7: Disetujui
B8: 46174 | C8: Keluar | D8: 150000 | E8: beli gula 5 kg | F8: Bahan Baku | G8: Disetujui
B9: 46175 | C9: Masuk | D9: 380000 | E9: jualan
B10: 46175 | C10: Keluar | D10: 25000 | E10: bensin antar pesanan
B11: 46176 | C11: Masuk | D11: 620000 | E11: pesanan katering 20 box | F11: Pendapatan Jasa | G11: Disetujui
B12: 46176 | C12: Keluar | D12: 300000 | E12: belanja pasar | F12: Bahan Baku | G12: Disetujui
B13: 46177 | C13: Keluar | D13: 500000 | E13: bayar listrik | F13: Listrik & Air | G13: Disetujui
B15: Perhatikan: kolom Kategori dan Status boleh kosong saat pemilik usaha mencatat. Admin yang melengkapi kemudian.

Sheet Data Grafik
A1: Data bantu untuk kartu & grafik Dashboard — tidak perlu diubah
A3: Metrik | B3: Bulan Ini | C3: Bulan Lalu
A4: Uang Masuk | B4: =SUMIFS(Transaksi!$C:$C,Transaksi!$J:$J,Dashboard!$C$8,Transaksi!$B:$B,"Masuk") | C4: =SUMIFS(Transaksi!$C:$C,Transaksi!$J:$J,Dashboard!$F$8,Transaksi!$B:$B,"Masuk")
A5: Uang Keluar | B5: =SUMIFS(Transaksi!$C:$C,Transaksi!$J:$J,Dashboard!$C$8,Transaksi!$B:$B,"Keluar") | C5: =SUMIFS(Transaksi!$C:$C,Transaksi!$J:$J,Dashboard!$F$8,Transaksi!$B:$B,"Keluar")
A6: Laba / Rugi | B6: =$B$4-$B$5 | C6: =$C$4-$C$5
A7: Saldo Kas | B7: =IF('Profil Usaha'!$C$14="",0,'Profil Usaha'!$C$14)+SUMIFS(Transaksi!$C:$C,Transaksi!$J:$J,"<="&Dashboard!$C$8,Transaksi!$B:$B,"Masuk")-SUMIFS(Transaksi!$C:$C,Transaksi!$J:$J,"<="&Dashboard!$C$8,Transaksi!$B:$B,"Keluar") | C7: =IF('Profil Usaha'!$C$14="",0,'Profil Usaha'!$C$14)+SUMIFS(Transaksi!$C:$C,Transaksi!$J:$J,"<="&Dashboard!$F$8,Transaksi!$B:$B,"Masuk")-SUMIFS(Transaksi!$C:$C,Transaksi!$J:$J,"<="&Dashboard!$F$8,Transaksi!$B:$B,"Keluar")
A8: Jumlah Transaksi | B8: =COUNTIFS(Transaksi!$J:$J,Dashboard!$C$8) | C8: =COUNTIFS(Transaksi!$J:$J,Dashboard!$F$8)
A9: Belum Dikategorikan | B9: =COUNTIFS(Transaksi!$J:$J,Dashboard!$C$8,Transaksi!$E:$E,"")
A10: Belum Disetujui | B10: =COUNTIFS(Transaksi!$J:$J,Dashboard!$C$8,Transaksi!$G:$G,"<>Disetujui")
A11: Transaksi Terakhir Dicatat | B11: =IF(COUNT(Transaksi!$A:$A)=0,"-",MAX(Transaksi!$A:$A))
A14: Bulan | B14: Kunci | C14: Uang Masuk | D14: Uang Keluar | E14: Laba / Rugi
A15: =CHOOSE(1,"Jan","Feb","Mar","Apr","Mei","Jun","Jul","Agu","Sep","Okt","Nov","Des") | B15: =TEXT(DATE(Dashboard!$F$6,1,1),"yyyy-mm") | C15: =SUMIFS(Transaksi!$C:$C,Transaksi!$J:$J,$B15,Transaksi!$B:$B,"Masuk") | D15: =SUMIFS(Transaksi!$C:$C,Transaksi!$J:$J,$B15,Transaksi!$B:$B,"Keluar") | E15: =$C15-$D15
A16: =CHOOSE(2,"Jan","Feb","Mar","Apr","Mei","Jun","Jul","Agu","Sep","Okt","Nov","Des") | B16: =TEXT(DATE(Dashboard!$F$6,2,1),"yyyy-mm") | C16: =SUMIFS(Transaksi!$C:$C,Transaksi!$J:$J,$B16,Transaksi!$B:$B,"Masuk") | D16: =SUMIFS(Transaksi!$C:$C,Transaksi!$J:$J,$B16,Transaksi!$B:$B,"Keluar") | E16: =$C16-$D16
A17: =CHOOSE(3,"Jan","Feb","Mar","Apr","Mei","Jun","Jul","Agu","Sep","Okt","Nov","Des") | B17: =TEXT(DATE(Dashboard!$F$6,3,1),"yyyy-mm") | C17: =SUMIFS(Transaksi!$C:$C,Transaksi!$J:$J,$B17,Transaksi!$B:$B,"Masuk") | D17: =SUMIFS(Transaksi!$C:$C,Transaksi!$J:$J,$B17,Transaksi!$B:$B,"Keluar") | E17: =$C17-$D17
A18: =CHOOSE(4,"Jan","Feb","Mar","Apr","Mei","Jun","Jul","Agu","Sep","Okt","Nov","Des") | B18: =TEXT(DATE(Dashboard!$F$6,4,1),"yyyy-mm") | C18: =SUMIFS(Transaksi!$C:$C,Transaksi!$J:$J,$B18,Transaksi!$B:$B,"Masuk") | D18: =SUMIFS(Transaksi!$C:$C,Transaksi!$J:$J,$B18,Transaksi!$B:$B,"Keluar") | E18: =$C18-$D18
A19: =CHOOSE(5,"Jan","Feb","Mar","Apr","Mei","Jun","Jul","Agu","Sep","Okt","Nov","Des") | B19: =TEXT(DATE(Dashboard!$F$6,5,1),"yyyy-mm") | C19: =SUMIFS(Transaksi!$C:$C,Transaksi!$J:$J,$B19,Transaksi!$B:$B,"Masuk") | D19: =SUMIFS(Transaksi!$C:$C,Transaksi!$J:$J,$B19,Transaksi!$B:$B,"Keluar") | E19: =$C19-$D19
A20: =CHOOSE(6,"Jan","Feb","Mar","Apr","Mei","Jun","Jul","Agu","Sep","Okt","Nov","Des") | B20: =TEXT(DATE(Dashboard!$F$6,6,1),"yyyy-mm") | C20: =SUMIFS(Transaksi!$C:$C,Transaksi!$J:$J,$B20,Transaksi!$B:$B,"Masuk") | D20: =SUMIFS(Transaksi!$C:$C,Transaksi!$J:$J,$B20,Transaksi!$B:$B,"Keluar") | E20: =$C20-$D20
A21: =CHOOSE(7,"Jan","Feb","Mar","Apr","Mei","Jun","Jul","Agu","Sep","Okt","Nov","Des") | B21: =TEXT(DATE(Dashboard!$F$6,7,1),"yyyy-mm") | C21: =SUMIFS(Transaksi!$C:$C,Transaksi!$J:$J,$B21,Transaksi!$B:$B,"Masuk") | D21: =SUMIFS(Transaksi!$C:$C,Transaksi!$J:$J,$B21,Transaksi!$B:$B,"Keluar") | E21: =$C21-$D21
A22: =CHOOSE(8,"Jan","Feb","Mar","Apr","Mei","Jun","Jul","Agu","Sep","Okt","Nov","Des") | B22: =TEXT(DATE(Dashboard!$F$6,8,1),"yyyy-mm") | C22: =SUMIFS(Transaksi!$C:$C,Transaksi!$J:$J,$B22,Transaksi!$B:$B,"Masuk") | D22: =SUMIFS(Transaksi!$C:$C,Transaksi!$J:$J,$B22,Transaksi!$B:$B,"Keluar") | E22: =$C22-$D22
A23: =CHOOSE(9,"Jan","Feb","Mar","Apr","Mei","Jun","Jul","Agu","Sep","Okt","Nov","Des") | B23: =TEXT(DATE(Dashboard!$F$6,9,1),"yyyy-mm") | C23: =SUMIFS(Transaksi!$C:$C,Transaksi!$J:$J,$B23,Transaksi!$B:$B,"Masuk") | D23: =SUMIFS(Transaksi!$C:$C,Transaksi!$J:$J,$B23,Transaksi!$B:$B,"Keluar") | E23: =$C23-$D23
A24: =CHOOSE(10,"Jan","Feb","Mar","Apr","Mei","Jun","Jul","Agu","Sep","Okt","Nov","Des") | B24: =TEXT(DATE(Dashboard!$F$6,10,1),"yyyy-mm") | C24: =SUMIFS(Transaksi!$C:$C,Transaksi!$J:$J,$B24,Transaksi!$B:$B,"Masuk") | D24: =SUMIFS(Transaksi!$C:$C,Transaksi!$J:$J,$B24,Transaksi!$B:$B,"Keluar") | E24: =$C24-$D24
A25: =CHOOSE(11,"Jan","Feb","Mar","Apr","Mei","Jun","Jul","Agu","Sep","Okt","Nov","Des") | B25: =TEXT(DATE(Dashboard!$F$6,11,1),"yyyy-mm") | C25: =SUMIFS(Transaksi!$C:$C,Transaksi!$J:$J,$B25,Transaksi!$B:$B,"Masuk") | D25: =SUMIFS(Transaksi!$C:$C,Transaksi!$J:$J,$B25,Transaksi!$B:$B,"Keluar") | E25: =$C25-$D25
A26: =CHOOSE(12,"Jan","Feb","Mar","Apr","Mei","Jun","Jul","Agu","Sep","Okt","Nov","Des") | B26: =TEXT(DATE(Dashboard!$F$6,12,1),"yyyy-mm") | C26: =SUMIFS(Transaksi!$C:$C,Transaksi!$J:$J,$B26,Transaksi!$B:$B,"Masuk") | D26: =SUMIFS(Transaksi!$C:$C,Transaksi!$J:$J,$B26,Transaksi!$B:$B,"Keluar") | E26: =$C26-$D26
A29: Kategori Pengeluaran | B29: Jumlah | C29: Nilai Unik (bantu)
A30: =Kategori!$C$7 | B30: =SUMIFS(Transaksi!$C:$C,Transaksi!$J:$J,Dashboard!$C$8,Transaksi!$B:$B,"Keluar",Transaksi!$E:$E,$A30) | C30: =IF($B30<=0,0,$B30+ROW()/1000000)
A31: =Kategori!$C$8 | B31: =SUMIFS(Transaksi!$C:$C,Transaksi!$J:$J,Dashboard!$C$8,Transaksi!$B:$B,"Keluar",Transaksi!$E:$E,$A31) | C31: =IF($B31<=0,0,$B31+ROW()/1000000)
A32: =Kategori!$C$9 | B32: =SUMIFS(Transaksi!$C:$C,Transaksi!$J:$J,Dashboard!$C$8,Transaksi!$B:$B,"Keluar",Transaksi!$E:$E,$A32) | C32: =IF($B32<=0,0,$B32+ROW()/1000000)
A33: =Kategori!$C$10 | B33: =SUMIFS(Transaksi!$C:$C,Transaksi!$J:$J,Dashboard!$C$8,Transaksi!$B:$B,"Keluar",Transaksi!$E:$E,$A33) | C33: =IF($B33<=0,0,$B33+ROW()/1000000)
